In Java, try, catch, and finally blocks are used for handling exceptions. This mechanism allows developers to manage runtime errors in a structured way, ensuring that the program can handle errors gracefully and execute cleanup code regardless of whether an exception occurs.

try Block
The try block contains code that might throw an exception. If an exception occurs within the try block, the control is transferred to the corresponding catch block.

catch Block
The catch block handles the exception thrown by the try block. You can have multiple catch blocks to handle different types of exceptions separately.

finally Block
The finally block contains code that will always execute, regardless of whether an exception was thrown or caught. It is typically used for cleanup activities, such as closing files or releasing resources.

Basic Syntax

try {
    // Code that may throw an exception
} catch (ExceptionType1 e1) {
    // Handle ExceptionType1
} catch (ExceptionType2 e2) {
    // Handle ExceptionType2
} finally {
    // Code that will always execute
}
Example
Here is a simple example demonstrating the usage of try, catch, and finally blocks:

public class ExceptionHandlingExample {
    public static void main(String[] args) {
        try {
            int[] numbers = {1, 2, 3};
            System.out.println(numbers[3]); // This will throw ArrayIndexOutOfBoundsException
        } catch (ArrayIndexOutOfBoundsException e) {
            System.out.println("Exception caught: " + e.getMessage());
        } finally {
            System.out.println("This is the finally block.");
        }
    }
}
Output:

csharp
Copy code
Exception caught: Index 3 out of bounds for length 3
This is the finally block.
Detailed Explanation
try Block:

The code inside the try block is executed first.
If no exception occurs, the catch block is skipped, and the finally block is executed.
If an exception occurs, the control is transferred to the appropriate catch block.
catch Block:

Each catch block is an exception handler that handles the type of exception specified.
If an exception of the specified type occurs in the try block, the corresponding catch block is executed.
You can have multiple catch blocks to handle different types of exceptions.
If the exception type does not match any catch block, the program will terminate unless the exception is handled by a higher-level try-catch.
finally Block:

The finally block is executed after the try and catch blocks, regardless of whether an exception was thrown or caught.
It is typically used for cleanup code such as closing files, releasing resources, etc.
The finally block is optional but recommended when dealing with resources that need to be released.
Multiple Catch Blocks
You can have multiple catch blocks to handle different types of exceptions separately.

public class MultipleCatchExample {
    public static void main(String[] args) {
        try {
            int[] numbers = {1, 2, 3};
            System.out.println(numbers[3]); // This will throw ArrayIndexOutOfBoundsException
            int result = 10 / 0; // This will throw ArithmeticException
        } catch (ArrayIndexOutOfBoundsException e) {
            System.out.println("ArrayIndexOutOfBoundsException caught: " + e.getMessage());
        } catch (ArithmeticException e) {
            System.out.println("ArithmeticException caught: " + e.getMessage());
        } finally {
            System.out.println("This is the finally block.");
        }
    }
}
Output:

csharp
Copy code
ArrayIndexOutOfBoundsException caught: Index 3 out of bounds for length 3
This is the finally block.
Catching Multiple Exceptions in a Single catch Block
Since Java 7, you can catch multiple exceptions in a single catch block using the pipe (|) operator.

public class MultiCatchExample {
    public static void main(String[] args) {
        try {
            int[] numbers = {1, 2, 3};
            System.out.println(numbers[3]); // This will throw ArrayIndexOutOfBoundsException
            int result = 10 / 0; // This will throw ArithmeticException
        } catch (ArrayIndexOutOfBoundsException | ArithmeticException e) {
            System.out.println("Exception caught: " + e.getMessage());
        } finally {
            System.out.println("This is the finally block.");
        }
    }
}
Output:

Exception caught: Index 3 out of bounds for length 3
This is the finally block.
Summary
The try, catch, and finally blocks in Java provide a powerful mechanism for handling runtime exceptions. By using these blocks, you can ensure that your program can handle errors gracefully and execute necessary cleanup code regardless of whether an exception occurs. Proper use of these constructs leads to more robust and maintainable code.







